load python 3.12.0.
remove Scientific Linux 7 libraries.
load Scientific Linux 7 libraries.
load tcltk 8.5.13 (GCC) library and binaries.
remove Scientific Linux 7 libraries.
load Scientific Linux 7 libraries.
Traceback (most recent call last):
  File "/home/WUR/zhou111/.local/lib/python3.12/site-packages/xarray/backends/file_manager.py", line 211, in _acquire_with_cache_info
    file = self._cache[self._key]
           ~~~~~~~~~~~^^^^^^^^^^^
  File "/home/WUR/zhou111/.local/lib/python3.12/site-packages/xarray/backends/lru_cache.py", line 56, in __getitem__
    value = self._cache[key]
            ~~~~~~~~~~~^^^^^
KeyError: [<class 'netCDF4._netCDF4.Dataset'>, ('/lustre/nobackup/WUR/ESG/zhou111/Model_Results/1_Yp_WOFOST/Rhine/soybean_Yp_his_org.nc',), 'a', (('clobber', True), ('diskless', False), ('format', 'NETCDF4'), ('persist', False)), 'fd3d56ef-fa01-4baf-9e3e-47480ded48af']

During handling of the above exception, another exception occurred:

Traceback (most recent call last):
  File "/lustre/nobackup/WUR/ESG/zhou111/Code/Data_Processing/Result_Analysis/1_Yp_Cult_SD/1_Get_Yp_SD_tsum.py", line 66, in <module>
    ds.to_netcdf(output_ncfile)
  File "/home/WUR/zhou111/.local/lib/python3.12/site-packages/xarray/core/dataset.py", line 2372, in to_netcdf
    return to_netcdf(  # type: ignore[return-value]  # mypy cannot resolve the overloads:(
           ^^^^^^^^^^^^^^^^^^^^^^^^^^^^^^^^^^^^^^^^^^^^^^^^^^^^^^^^^^^^^^^^^^^^^^^^^^^^^^^
  File "/home/WUR/zhou111/.local/lib/python3.12/site-packages/xarray/backends/api.py", line 1856, in to_netcdf
    store = store_open(target, mode, format, group, **kwargs)
            ^^^^^^^^^^^^^^^^^^^^^^^^^^^^^^^^^^^^^^^^^^^^^^^^^
  File "/home/WUR/zhou111/.local/lib/python3.12/site-packages/xarray/backends/netCDF4_.py", line 452, in open
    return cls(manager, group=group, mode=mode, lock=lock, autoclose=autoclose)
           ^^^^^^^^^^^^^^^^^^^^^^^^^^^^^^^^^^^^^^^^^^^^^^^^^^^^^^^^^^^^^^^^^^^^
  File "/home/WUR/zhou111/.local/lib/python3.12/site-packages/xarray/backends/netCDF4_.py", line 393, in __init__
    self.format = self.ds.data_model
                  ^^^^^^^
  File "/home/WUR/zhou111/.local/lib/python3.12/site-packages/xarray/backends/netCDF4_.py", line 461, in ds
    return self._acquire()
           ^^^^^^^^^^^^^^^
  File "/home/WUR/zhou111/.local/lib/python3.12/site-packages/xarray/backends/netCDF4_.py", line 455, in _acquire
    with self._manager.acquire_context(needs_lock) as root:
  File "/shared/legacyapps/python/3.12.0/lib/python3.12/contextlib.py", line 137, in __enter__
    return next(self.gen)
           ^^^^^^^^^^^^^^
  File "/home/WUR/zhou111/.local/lib/python3.12/site-packages/xarray/backends/file_manager.py", line 199, in acquire_context
    file, cached = self._acquire_with_cache_info(needs_lock)
                   ^^^^^^^^^^^^^^^^^^^^^^^^^^^^^^^^^^^^^^^^^
  File "/home/WUR/zhou111/.local/lib/python3.12/site-packages/xarray/backends/file_manager.py", line 217, in _acquire_with_cache_info
    file = self._opener(*self._args, **kwargs)
           ^^^^^^^^^^^^^^^^^^^^^^^^^^^^^^^^^^^
  File "src/netCDF4/_netCDF4.pyx", line 2469, in netCDF4._netCDF4.Dataset.__init__
  File "src/netCDF4/_netCDF4.pyx", line 2028, in netCDF4._netCDF4._ensure_nc_success
PermissionError: [Errno 13] Permission denied: '/lustre/nobackup/WUR/ESG/zhou111/Model_Results/1_Yp_WOFOST/Rhine/soybean_Yp_his_org.nc'
